Workbook
Name TypeList: lists!$A$1:$A$13

Sheet _empty

Sheet Колонки и примеры
A1: id | B1: type | C1: ukr | D1: rus | E1: eng | F1: ger | G1: ukr_sub | H1: rus_sub | I1: eng_sub | J1: ger_sub | K1: href | L1: meta
A2: 1 | B2: heroImage | C2: images/hero.jpg | D2: images/hero.jpg | E2: images/hero.jpg | F2: images/hero.jpg | L2: w=1200;h=520;resizeMode=cover
A3: 2 | B3: eyebrow | C3: Академія краси | D3: Академия красоты | E3: Beauty Academy | F3: Beauty Academy
A4: 3 | B4: title | C4: Майстерність перманентного макіяжу | D4: Мастерство перманентного макияжа | E4: Master permanent makeup | F4: Meister der Permanent Make-up
A5: 4 | B5: subtitle | C5: Навчайтеся у найкращих практиків | D5: Учитесь у лучших практиков | E5: Learn from top professionals | F5: Lernen Sie von den besten Profis
A6: 5 | B6: text | C6: Цей текст відображається як звичайний абзац. | D6: Этот текст выводится как обычный параграф. | E6: This text is rendered as a normal paragraph. | F6: Dieser Text wird als normaler Absatz angezeigt.
A7: 6 | B7: image | C7: images/example.jpg | D7: images/example.jpg | E7: images/example.jpg | F7: images/example.jpg | L7: w=600;h=400;resizeMode=contain
A8: 7 | B8: gif | C8: images/animation.gif | D8: images/animation.gif | E8: images/animation.gif | F8: images/animation.gif | L8: w=400;h=225;resizeMode=contain
A9: 8 | B9: card | C9: Заголовок карточки | D9: Заголовок карточки | E9: Card title | F9: Kartenüberschrift | G9: Опис карточки українською | H9: Описание карточки на русском | I9: Card description in English | J9: Kartenbeschreibung auf Deutsch | K9: /lesson-example
A10: 9 | B10: video | C10: https://www.youtube.com/watch?v=dQw4w9WgXcQ | D10: https://www.youtube.com/watch?v=dQw4w9WgXcQ | E10: https://www.youtube.com/watch?v=dQw4w9WgXcQ | F10: https://www.youtube.com/watch?v=dQw4w9WgXcQ
A11: 10 | B11: link | C11: Детальніше про курс | D11: Подробнее о курсе | E11: Read more about the course | F11: Mehr über den Kurs | K11: /course
A12: 11 | B12: item | C12: Пункт списку UA | D12: Пункт списка RU | E12: List item EN | F12: Listenelement DE
A13: 12 | B13: navigationButtons | C13: Наступний урок | D13: Следующий урок | E13: Next lesson | F13: Nächste Lektion | K13: /next-page
A14: 13 | B14: languageSwitcher | C14: Перемикач мови | D14: Переключатель языка | E14: Language switcher | F14: Sprachumschalter | G14: Змінити мову | H14: Изменить язык | I14: Change language | J14: Sprache ändern | K14: /language
A15: 14 | B15: spacer | C15: Секция | D15: Секция | E15: Section | F15: Abschnitt
A16: 15 | B16: quiz | C16: Квиз: проверьте себя | D16: Квиз: проверьте себя | E16: Quiz: test yourself | F16: Quiz: test yourself | K16: quiz1
A17: 16 | B17: timer | L17: seconds=180
A18: 17 | B18: checklist | C18: Список задач | D18: Список задач | E18: Checklist | F18: Checkliste | K18: checklist1

Sheet Шаблон ввода_DO_NOT_DELETE
A1: id | B1: type | C1: ukr | D1: rus | E1: eng | F1: ger | G1: ukr_sub | H1: rus_sub | I1: eng_sub | J1: ger_sub | K1: href | L1: meta
A2: 1 | C2: =IFERROR(INDEX('Колонки и примеры'!C:C,MATCH($B2,'Колонки и примеры'!$B:$B,0)),"") | D2: =IFERROR(INDEX('Колонки и примеры'!D:D,MATCH($B2,'Колонки и примеры'!$B:$B,0)),"") | E2: =IFERROR(INDEX('Колонки и примеры'!E:E,MATCH($B2,'Колонки и примеры'!$B:$B,0)),"") | F2: =IFERROR(INDEX('Колонки и примеры'!F:F,MATCH($B2,'Колонки и примеры'!$B:$B,0)),"") | G2: =IFERROR(INDEX('Колонки и примеры'!G:G,MATCH($B2,'Колонки и примеры'!$B:$B,0)),"") | H2: =IFERROR(INDEX('Колонки и примеры'!H:H,MATCH($B2,'Колонки и примеры'!$B:$B,0)),"") | I2: =IFERROR(INDEX('Колонки и примеры'!I:I,MATCH($B2,'Колонки и примеры'!$B:$B,0)),"") | J2: =IFERROR(INDEX('Колонки и примеры'!J:J,MATCH($B2,'Колонки и примеры'!$B:$B,0)),"") | K2: =IFERROR(INDEX('Колонки и примеры'!K:K,MATCH($B2,'Колонки и примеры'!$B:$B,0)),"") | L2: =IFERROR(INDEX('Колонки и примеры'!L:L,MATCH($B2,'Колонки и примеры'!$B:$B,0)),"") | N2: 1. Выберите type из выпадающего списка
A3: 2 | C3: =IFERROR(INDEX('Колонки и примеры'!C:C,MATCH($B3,'Колонки и примеры'!$B:$B,0)),"") | D3: =IFERROR(INDEX('Колонки и примеры'!D:D,MATCH($B3,'Колонки и примеры'!$B:$B,0)),"") | E3: =IFERROR(INDEX('Колонки и примеры'!E:E,MATCH($B3,'Колонки и примеры'!$B:$B,0)),"") | F3: =IFERROR(INDEX('Колонки и примеры'!F:F,MATCH($B3,'Колонки и примеры'!$B:$B,0)),"") | G3: =IFERROR(INDEX('Колонки и примеры'!G:G,MATCH($B3,'Колонки и примеры'!$B:$B,0)),"") | H3: =IFERROR(INDEX('Колонки и примеры'!H:H,MATCH($B3,'Колонки и примеры'!$B:$B,0)),"") | I3: =IFERROR(INDEX('Колонки и примеры'!I:I,MATCH($B3,'Колонки и примеры'!$B:$B,0)),"") | J3: =IFERROR(INDEX('Колонки и примеры'!J:J,MATCH($B3,'Колонки и примеры'!$B:$B,0)),"") | K3: =IFERROR(INDEX('Колонки и примеры'!K:K,MATCH($B3,'Колонки и примеры'!$B:$B,0)),"") | L3: =IFERROR(INDEX('Колонки и примеры'!L:L,MATCH($B3,'Колонки и примеры'!$B:$B,0)),"") | N3: 2. Пример автоматически подтянется
A4: 3 | C4: =IFERROR(INDEX('Колонки и примеры'!C:C,MATCH($B4,'Колонки и примеры'!$B:$B,0)),"") | D4: =IFERROR(INDEX('Колонки и примеры'!D:D,MATCH($B4,'Колонки и примеры'!$B:$B,0)),"") | E4: =IFERROR(INDEX('Колонки и примеры'!E:E,MATCH($B4,'Колонки и примеры'!$B:$B,0)),"") | F4: =IFERROR(INDEX('Колонки и примеры'!F:F,MATCH($B4,'Колонки и примеры'!$B:$B,0)),"") | G4: =IFERROR(INDEX('Колонки и примеры'!G:G,MATCH($B4,'Колонки и примеры'!$B:$B,0)),"") | H4: =IFERROR(INDEX('Колонки и примеры'!H:H,MATCH($B4,'Колонки и примеры'!$B:$B,0)),"") | I4: =IFERROR(INDEX('Колонки и примеры'!I:I,MATCH($B4,'Колонки и примеры'!$B:$B,0)),"") | J4: =IFERROR(INDEX('Колонки и примеры'!J:J,MATCH($B4,'Колонки и примеры'!$B:$B,0)),"") | K4: =IFERROR(INDEX('Колонки и примеры'!K:K,MATCH($B4,'Колонки и примеры'!$B:$B,0)),"") | L4: =IFERROR(INDEX('Колонки и примеры'!L:L,MATCH($B4,'Колонки и примеры'!$B:$B,0)),"") | N4: 3. Замените пример своим текстом
A5: 4 | C5: =IFERROR(INDEX('Колонки и примеры'!C:C,MATCH($B5,'Колонки и примеры'!$B:$B,0)),"") | D5: =IFERROR(INDEX('Колонки и примеры'!D:D,MATCH($B5,'Колонки и примеры'!$B:$B,0)),"") | E5: =IFERROR(INDEX('Колонки и примеры'!E:E,MATCH($B5,'Колонки и примеры'!$B:$B,0)),"") | F5: =IFERROR(INDEX('Колонки и примеры'!F:F,MATCH($B5,'Колонки и примеры'!$B:$B,0)),"") | G5: =IFERROR(INDEX('Колонки и примеры'!G:G,MATCH($B5,'Колонки и примеры'!$B:$B,0)),"") | H5: =IFERROR(INDEX('Колонки и примеры'!H:H,MATCH($B5,'Колонки и примеры'!$B:$B,0)),"") | I5: =IFERROR(INDEX('Колонки и примеры'!I:I,MATCH($B5,'Колонки и примеры'!$B:$B,0)),"") | J5: =IFERROR(INDEX('Колонки и примеры'!J:J,MATCH($B5,'Колонки и примеры'!$B:$B,0)),"") | K5: =IFERROR(INDEX('Колонки и примеры'!K:K,MATCH($B5,'Колонки и примеры'!$B:$B,0)),"") | L5: =IFERROR(INDEX('Колонки и примеры'!L:L,MATCH($B5,'Колонки и примеры'!$B:$B,0)),"")
A6: 5 | C6: =IFERROR(INDEX('Колонки и примеры'!C:C,MATCH($B6,'Колонки и примеры'!$B:$B,0)),"") | D6: =IFERROR(INDEX('Колонки и примеры'!D:D,MATCH($B6,'Колонки и примеры'!$B:$B,0)),"") | E6: =IFERROR(INDEX('Колонки и примеры'!E:E,MATCH($B6,'Колонки и примеры'!$B:$B,0)),"") | F6: =IFERROR(INDEX('Колонки и примеры'!F:F,MATCH($B6,'Колонки и примеры'!$B:$B,0)),"") | G6: =IFERROR(INDEX('Колонки и примеры'!G:G,MATCH($B6,'Колонки и примеры'!$B:$B,0)),"") | H6: =IFERROR(INDEX('Колонки и примеры'!H:H,MATCH($B6,'Колонки и примеры'!$B:$B,0)),"") | I6: =IFERROR(INDEX('Колонки и примеры'!I:I,MATCH($B6,'Колонки и примеры'!$B:$B,0)),"") | J6: =IFERROR(INDEX('Колонки и примеры'!J:J,MATCH($B6,'Колонки и примеры'!$B:$B,0)),"") | K6: =IFERROR(INDEX('Колонки и примеры'!K:K,MATCH($B6,'Колонки и примеры'!$B:$B,0)),"") | L6: =IFERROR(INDEX('Колонки и примеры'!L:L,MATCH($B6,'Колонки и примеры'!$B:$B,0)),"")
A7: 6 | C7: =IFERROR(INDEX('Колонки и примеры'!C:C,MATCH($B7,'Колонки и примеры'!$B:$B,0)),"") | D7: =IFERROR(INDEX('Колонки и примеры'!D:D,MATCH($B7,'Колонки и примеры'!$B:$B,0)),"") | E7: =IFERROR(INDEX('Колонки и примеры'!E:E,MATCH($B7,'Колонки и примеры'!$B:$B,0)),"") | F7: =IFERROR(INDEX('Колонки и примеры'!F:F,MATCH($B7,'Колонки и примеры'!$B:$B,0)),"") | G7: =IFERROR(INDEX('Колонки и примеры'!G:G,MATCH($B7,'Колонки и примеры'!$B:$B,0)),"") | H7: =IFERROR(INDEX('Колонки и примеры'!H:H,MATCH($B7,'Колонки и примеры'!$B:$B,0)),"") | I7: =IFERROR(INDEX('Колонки и примеры'!I:I,MATCH($B7,'Колонки и примеры'!$B:$B,0)),"") | J7: =IFERROR(INDEX('Колонки и примеры'!J:J,MATCH($B7,'Колонки и примеры'!$B:$B,0)),"") | K7: =IFERROR(INDEX('Колонки и примеры'!K:K,MATCH($B7,'Колонки и примеры'!$B:$B,0)),"") | L7: =IFERROR(INDEX('Колонки и примеры'!L:L,MATCH($B7,'Колонки и примеры'!$B:$B,0)),"")
A8: 7 | C8: =IFERROR(INDEX('Колонки и примеры'!C:C,MATCH($B8,'Колонки и примеры'!$B:$B,0)),"") | D8: =IFERROR(INDEX('Колонки и примеры'!D:D,MATCH($B8,'Колонки и примеры'!$B:$B,0)),"") | E8: =IFERROR(INDEX('Колонки и примеры'!E:E,MATCH($B8,'Колонки и примеры'!$B:$B,0)),"") | F8: =IFERROR(INDEX('Колонки и примеры'!F:F,MATCH($B8,'Колонки и примеры'!$B:$B,0)),"") | G8: =IFERROR(INDEX('Колонки и примеры'!G:G,MATCH($B8,'Колонки и примеры'!$B:$B,0)),"") | H8: =IFERROR(INDEX('Колонки и примеры'!H:H,MATCH($B8,'Колонки и примеры'!$B:$B,0)),"") | I8: =IFERROR(INDEX('Колонки и примеры'!I:I,MATCH($B8,'Колонки и примеры'!$B:$B,0)),"") | J8: =IFERROR(INDEX('Колонки и примеры'!J:J,MATCH($B8,'Колонки и примеры'!$B:$B,0)),"") | K8: =IFERROR(INDEX('Колонки и примеры'!K:K,MATCH($B8,'Колонки и примеры'!$B:$B,0)),"") | L8: =IFERROR(INDEX('Колонки и примеры'!L:L,MATCH($B8,'Колонки и примеры'!$B:$B,0)),"")
A9: 8 | C9: =IFERROR(INDEX('Колонки и примеры'!C:C,MATCH($B9,'Колонки и примеры'!$B:$B,0)),"") | D9: =IFERROR(INDEX('Колонки и примеры'!D:D,MATCH($B9,'Колонки и примеры'!$B:$B,0)),"") | E9: =IFERROR(INDEX('Колонки и примеры'!E:E,MATCH($B9,'Колонки и примеры'!$B:$B,0)),"") | F9: =IFERROR(INDEX('Колонки и примеры'!F:F,MATCH($B9,'Колонки и примеры'!$B:$B,0)),"") | G9: =IFERROR(INDEX('Колонки и примеры'!G:G,MATCH($B9,'Колонки и примеры'!$B:$B,0)),"") | H9: =IFERROR(INDEX('Колонки и примеры'!H:H,MATCH($B9,'Колонки и примеры'!$B:$B,0)),"") | I9: =IFERROR(INDEX('Колонки и примеры'!I:I,MATCH($B9,'Колонки и примеры'!$B:$B,0)),"") | J9: =IFERROR(INDEX('Колонки и примеры'!J:J,MATCH($B9,'Колонки и примеры'!$B:$B,0)),"") | K9: =IFERROR(INDEX('Колонки и примеры'!K:K,MATCH($B9,'Колонки и примеры'!$B:$B,0)),"") | L9: =IFERROR(INDEX('Колонки и примеры'!L:L,MATCH($B9,'Колонки и примеры'!$B:$B,0)),"")
A10: 9 | C10: =IFERROR(INDEX('Колонки и примеры'!C:C,MATCH($B10,'Колонки и примеры'!$B:$B,0)),"") | D10: =IFERROR(INDEX('Колонки и примеры'!D:D,MATCH($B10,'Колонки и примеры'!$B:$B,0)),"") | E10: =IFERROR(INDEX('Колонки и примеры'!E:E,MATCH($B10,'Колонки и примеры'!$B:$B,0)),"") | F10: =IFERROR(INDEX('Колонки и примеры'!F:F,MATCH($B10,'Колонки и примеры'!$B:$B,0)),"") | G10: =IFERROR(INDEX('Колонки и примеры'!G:G,MATCH($B10,'Колонки и примеры'!$B:$B,0)),"") | H10: =IFERROR(INDEX('Колонки и примеры'!H:H,MATCH($B10,'Колонки и примеры'!$B:$B,0)),"") | I10: =IFERROR(INDEX('Колонки и примеры'!I:I,MATCH($B10,'Колонки и примеры'!$B:$B,0)),"") | J10: =IFERROR(INDEX('Колонки и примеры'!J:J,MATCH($B10,'Колонки и примеры'!$B:$B,0)),"") | K10: =IFERROR(INDEX('Колонки и примеры'!K:K,MATCH($B10,'Колонки и примеры'!$B:$B,0)),"") | L10: =IFERROR(INDEX('Колонки и примеры'!L:L,MATCH($B10,'Колонки и примеры'!$B:$B,0)),"")
A11: 10 | C11: =IFERROR(INDEX('Колонки и примеры'!C:C,MATCH($B11,'Колонки и примеры'!$B:$B,0)),"") | D11: =IFERROR(INDEX('Колонки и примеры'!D:D,MATCH($B11,'Колонки и примеры'!$B:$B,0)),"") | E11: =IFERROR(INDEX('Колонки и примеры'!E:E,MATCH($B11,'Колонки и примеры'!$B:$B,0)),"") | F11: =IFERROR(INDEX('Колонки и примеры'!F:F,MATCH($B11,'Колонки и примеры'!$B:$B,0)),"") | G11: =IFERROR(INDEX('Колонки и примеры'!G:G,MATCH($B11,'Колонки и примеры'!$B:$B,0)),"") | H11: =IFERROR(INDEX('Колонки и примеры'!H:H,MATCH($B11,'Колонки и примеры'!$B:$B,0)),"") | I11: =IFERROR(INDEX('Колонки и примеры'!I:I,MATCH($B11,'Колонки и примеры'!$B:$B,0)),"") | J11: =IFERROR(INDEX('Колонки и примеры'!J:J,MATCH($B11,'Колонки и примеры'!$B:$B,0)),"") | K11: =IFERROR(INDEX('Колонки и примеры'!K:K,MATCH($B11,'Колонки и примеры'!$B:$B,0)),"") | L11: =IFERROR(INDEX('Колонки и примеры'!L:L,MATCH($B11,'Колонки и примеры'!$B:$B,0)),"")
A12: 11 | C12: =IFERROR(INDEX('Колонки и примеры'!C:C,MATCH($B12,'Колонки и примеры'!$B:$B,0)),"") | D12: =IFERROR(INDEX('Колонки и примеры'!D:D,MATCH($B12,'Колонки и примеры'!$B:$B,0)),"") | E12: =IFERROR(INDEX('Колонки и примеры'!E:E,MATCH($B12,'Колонки и примеры'!$B:$B,0)),"") | F12: =IFERROR(INDEX('Колонки и примеры'!F:F,MATCH($B12,'Колонки и примеры'!$B:$B,0)),"") | G12: =IFERROR(INDEX('Колонки и примеры'!G:G,MATCH($B12,'Колонки и примеры'!$B:$B,0)),"") | H12: =IFERROR(INDEX('Колонки и примеры'!H:H,MATCH($B12,'Колонки и примеры'!$B:$B,0)),"") | I12: =IFERROR(INDEX('Колонки и примеры'!I:I,MATCH($B12,'Колонки и примеры'!$B:$B,0)),"") | J12: =IFERROR(INDEX('Колонки и примеры'!J:J,MATCH($B12,'Колонки и примеры'!$B:$B,0)),"") | K12: =IFERROR(INDEX('Колонки и примеры'!K:K,MATCH($B12,'Колонки и примеры'!$B:$B,0)),"") | L12: =IFERROR(INDEX('Колонки и примеры'!L:L,MATCH($B12,'Колонки и примеры'!$B:$B,0)),"")
A13: 12 | C13: =IFERROR(INDEX('Колонки и примеры'!C:C,MATCH($B13,'Колонки и примеры'!$B:$B,0)),"") | D13: =IFERROR(INDEX('Колонки и примеры'!D:D,MATCH($B13,'Колонки и примеры'!$B:$B,0)),"") | E13: =IFERROR(INDEX('Колонки и примеры'!E:E,MATCH($B13,'Колонки и примеры'!$B:$B,0)),"") | F13: =IFERROR(INDEX('Колонки и примеры'!F:F,MATCH($B13,'Колонки и примеры'!$B:$B,0)),"") | G13: =IFERROR(INDEX('Колонки и примеры'!G:G,MATCH($B13,'Колонки и примеры'!$B:$B,0)),"") | H13: =IFERROR(INDEX('Колонки и примеры'!H:H,MATCH($B13,'Колонки и примеры'!$B:$B,0)),"") | I13: =IFERROR(INDEX('Колонки и примеры'!I:I,MATCH($B13,'Колонки и примеры'!$B:$B,0)),"") | J13: =IFERROR(INDEX('Колонки и примеры'!J:J,MATCH($B13,'Колонки и примеры'!$B:$B,0)),"") | K13: =IFERROR(INDEX('Колонки и примеры'!K:K,MATCH($B13,'Колонки и примеры'!$B:$B,0)),"") | L13: =IFERROR(INDEX('Колонки и примеры'!L:L,MATCH($B13,'Колонки и примеры'!$B:$B,0)),"")
A14: 13 | C14: =IFERROR(INDEX('Колонки и примеры'!C:C,MATCH($B14,'Колонки и примеры'!$B:$B,0)),"") | D14: =IFERROR(INDEX('Колонки и примеры'!D:D,MATCH($B14,'Колонки и примеры'!$B:$B,0)),"") | E14: =IFERROR(INDEX('Колонки и примеры'!E:E,MATCH($B14,'Колонки и примеры'!$B:$B,0)),"") | F14: =IFERROR(INDEX('Колонки и примеры'!F:F,MATCH($B14,'Колонки и примеры'!$B:$B,0)),"") | G14: =IFERROR(INDEX('Колонки и примеры'!G:G,MATCH($B14,'Колонки и примеры'!$B:$B,0)),"") | H14: =IFERROR(INDEX('Колонки и примеры'!H:H,MATCH($B14,'Колонки и примеры'!$B:$B,0)),"") | I14: =IFERROR(INDEX('Колонки и примеры'!I:I,MATCH($B14,'Колонки и примеры'!$B:$B,0)),"") | J14: =IFERROR(INDEX('Колонки и примеры'!J:J,MATCH($B14,'Колонки и примеры'!$B:$B,0)),"") | K14: =IFERROR(INDEX('Колонки и примеры'!K:K,MATCH($B14,'Колонки и примеры'!$B:$B,0)),"") | L14: =IFERROR(INDEX('Колонки и примеры'!L:L,MATCH($B14,'Колонки и примеры'!$B:$B,0)),"")
A15: 14 | C15: =IFERROR(INDEX('Колонки и примеры'!C:C,MATCH($B15,'Колонки и примеры'!$B:$B,0)),"") | D15: =IFERROR(INDEX('Колонки и примеры'!D:D,MATCH($B15,'Колонки и примеры'!$B:$B,0)),"") | E15: =IFERROR(INDEX('Колонки и примеры'!E:E,MATCH($B15,'Колонки и примеры'!$B:$B,0)),"") | F15: =IFERROR(INDEX('Колонки и примеры'!F:F,MATCH($B15,'Колонки и примеры'!$B:$B,0)),"") | G15: =IFERROR(INDEX('Колонки и примеры'!G:G,MATCH($B15,'Колонки и примеры'!$B:$B,0)),"") | H15: =IFERROR(INDEX('Колонки и примеры'!H:H,MATCH($B15,'Колонки и примеры'!$B:$B,0)),"") | I15: =IFERROR(INDEX('Колонки и примеры'!I:I,MATCH($B15,'Колонки и примеры'!$B:$B,0)),"") | J15: =IFERROR(INDEX('Колонки и примеры'!J:J,MATCH($B15,'Колонки и примеры'!$B:$B,0)),"") | K15: =IFERROR(INDEX('Колонки и примеры'!K:K,MATCH($B15,'Колонки и примеры'!$B:$B,0)),"") | L15: =IFERROR(INDEX('Колонки и примеры'!L:L,MATCH($B15,'Колонки и примеры'!$B:$B,0)),"")
A16: 15 | C16: =IFERROR(INDEX('Колонки и примеры'!C:C,MATCH($B16,'Колонки и примеры'!$B:$B,0)),"") | D16: =IFERROR(INDEX('Колонки и примеры'!D:D,MATCH($B16,'Колонки и примеры'!$B:$B,0)),"") | E16: =IFERROR(INDEX('Колонки и примеры'!E:E,MATCH($B16,'Колонки и примеры'!$B:$B,0)),"") | F16: =IFERROR(INDEX('Колонки и примеры'!F:F,MATCH($B16,'Колонки и примеры'!$B:$B,0)),"") | G16: =IFERROR(INDEX('Колонки и примеры'!G:G,MATCH($B16,'Колонки и примеры'!$B:$B,0)),"") | H16: =IFERROR(INDEX('Колонки и примеры'!H:H,MATCH($B16,'Колонки и примеры'!$B:$B,0)),"") | I16: =IFERROR(INDEX('Колонки и примеры'!I:I,MATCH($B16,'Колонки и примеры'!$B:$B,0)),"") | J16: =IFERROR(INDEX('Колонки и примеры'!J:J,MATCH($B16,'Колонки и примеры'!$B:$B,0)),"") | K16: =IFERROR(INDEX('Колонки и примеры'!K:K,MATCH($B16,'Колонки и примеры'!$B:$B,0)),"") | L16: =IFERROR(INDEX('Колонки и примеры'!L:L,MATCH($B16,'Колонки и примеры'!$B:$B,0)),"")
... A101: 100 | C101: =IFERROR(INDEX('Колонки и примеры'!C:C,MATCH($B101,'Колонки и примеры'!$B:$B,0)),"") | D101: =IFERROR(INDEX('Колонки и примеры'!D:D,MATCH($B101,'Колонки и примеры'!$B:$B,0)),"") | E101: =IFERROR(INDEX('Колонки и примеры'!E:E,MATCH($B101,'Колонки и примеры'!$B:$B,0)),"") | F101: =IFERROR(INDEX('Колонки и примеры'!F:F,MATCH($B101,'Колонки и примеры'!$B:$B,0)),"") | G101: =IFERROR(INDEX('Колонки и примеры'!G:G,MATCH($B101,'Колонки и примеры'!$B:$B,0)),"") | H101: =IFERROR(INDEX('Колонки и примеры'!H:H,MATCH($B101,'Колонки и примеры'!$B:$B,0)),"") | I101: =IFERROR(INDEX('Колонки и примеры'!I:I,MATCH($B101,'Колонки и примеры'!$B:$B,0)),"") | J101: =IFERROR(INDEX('Колонки и примеры'!J:J,MATCH($B101,'Колонки и примеры'!$B:$B,0)),"") | K101: =IFERROR(INDEX('Колонки и примеры'!K:K,MATCH($B101,'Колонки и примеры'!$B:$B,0)),"") | L101: =IFERROR(INDEX('Колонки и примеры'!L:L,MATCH($B101,'Колонки и примеры'!$B:$B,0)),"")
C102: =IFERROR(INDEX('Колонки и примеры'!C:C,MATCH($B101,'Колонки и примеры'!$B:$B,0)),"") | D102: =IFERROR(INDEX('Колонки и примеры'!D:D,MATCH($B101,'Колонки и примеры'!$B:$B,0)),"") | E102: =IFERROR(INDEX('Колонки и примеры'!E:E,MATCH($B101,'Колонки и примеры'!$B:$B,0)),"") | F102: =IFERROR(INDEX('Колонки и примеры'!F:F,MATCH($B101,'Колонки и примеры'!$B:$B,0)),"") | G102: =IFERROR(INDEX('Колонки и примеры'!G:G,MATCH($B101,'Колонки и примеры'!$B:$B,0)),"") | H102: =IFERROR(INDEX('Колонки и примеры'!H:H,MATCH($B101,'Колонки и примеры'!$B:$B,0)),"") | I102: =IFERROR(INDEX('Колонки и примеры'!I:I,MATCH($B101,'Колонки и примеры'!$B:$B,0)),"") | J102: =IFERROR(INDEX('Колонки и примеры'!J:J,MATCH($B101,'Колонки и примеры'!$B:$B,0)),"") | K102: =IFERROR(INDEX('Колонки и примеры'!K:K,MATCH($B101,'Колонки и примеры'!$B:$B,0)),"") | L102: =IFERROR(INDEX('Колонки и примеры'!L:L,MATCH($B101,'Колонки и примеры'!$B:$B,0)),"")
C103: =IFERROR(INDEX('Колонки и примеры'!C:C,MATCH($B101,'Колонки и примеры'!$B:$B,0)),"") | D103: =IFERROR(INDEX('Колонки и примеры'!D:D,MATCH($B101,'Колонки и примеры'!$B:$B,0)),"") | E103: =IFERROR(INDEX('Колонки и примеры'!E:E,MATCH($B101,'Колонки и примеры'!$B:$B,0)),"") | F103: =IFERROR(INDEX('Колонки и примеры'!F:F,MATCH($B101,'Колонки и примеры'!$B:$B,0)),"") | G103: =IFERROR(INDEX('Колонки и примеры'!G:G,MATCH($B101,'Колонки и примеры'!$B:$B,0)),"") | H103: =IFERROR(INDEX('Колонки и примеры'!H:H,MATCH($B101,'Колонки и примеры'!$B:$B,0)),"") | I103: =IFERROR(INDEX('Колонки и примеры'!I:I,MATCH($B101,'Колонки и примеры'!$B:$B,0)),"") | J103: =IFERROR(INDEX('Колонки и примеры'!J:J,MATCH($B101,'Колонки и примеры'!$B:$B,0)),"") | K103: =IFERROR(INDEX('Колонки и примеры'!K:K,MATCH($B101,'Колонки и примеры'!$B:$B,0)),"") | L103: =IFERROR(INDEX('Колонки и примеры'!L:L,MATCH($B101,'Колонки и примеры'!$B:$B,0)),"")
C104: =IFERROR(INDEX('Колонки и примеры'!C:C,MATCH($B101,'Колонки и примеры'!$B:$B,0)),"") | D104: =IFERROR(INDEX('Колонки и примеры'!D:D,MATCH($B101,'Колонки и примеры'!$B:$B,0)),"") | E104: =IFERROR(INDEX('Колонки и примеры'!E:E,MATCH($B101,'Колонки и примеры'!$B:$B,0)),"") | F104: =IFERROR(INDEX('Колонки и примеры'!F:F,MATCH($B101,'Колонки и примеры'!$B:$B,0)),"") | G104: =IFERROR(INDEX('Колонки и примеры'!G:G,MATCH($B101,'Колонки и примеры'!$B:$B,0)),"") | H104: =IFERROR(INDEX('Колонки и примеры'!H:H,MATCH($B101,'Колонки и примеры'!$B:$B,0)),"") | I104: =IFERROR(INDEX('Колонки и примеры'!I:I,MATCH($B101,'Колонки и примеры'!$B:$B,0)),"") | J104: =IFERROR(INDEX('Колонки и примеры'!J:J,MATCH($B101,'Колонки и примеры'!$B:$B,0)),"") | K104: =IFERROR(INDEX('Колонки и примеры'!K:K,MATCH($B101,'Колонки и примеры'!$B:$B,0)),"") | L104: =IFERROR(INDEX('Колонки и примеры'!L:L,MATCH($B101,'Колонки и примеры'!$B:$B,0)),"")
C105: =IFERROR(INDEX('Колонки и примеры'!C:C,MATCH($B101,'Колонки и примеры'!$B:$B,0)),"") | D105: =IFERROR(INDEX('Колонки и примеры'!D:D,MATCH($B101,'Колонки и примеры'!$B:$B,0)),"") | E105: =IFERROR(INDEX('Колонки и примеры'!E:E,MATCH($B101,'Колонки и примеры'!$B:$B,0)),"") | F105: =IFERROR(INDEX('Колонки и примеры'!F:F,MATCH($B101,'Колонки и примеры'!$B:$B,0)),"") | G105: =IFERROR(INDEX('Колонки и примеры'!G:G,MATCH($B101,'Колонки и примеры'!$B:$B,0)),"") | H105: =IFERROR(INDEX('Колонки и примеры'!H:H,MATCH($B101,'Колонки и примеры'!$B:$B,0)),"") | I105: =IFERROR(INDEX('Колонки и примеры'!I:I,MATCH($B101,'Колонки и примеры'!$B:$B,0)),"") | J105: =IFERROR(INDEX('Колонки и примеры'!J:J,MATCH($B101,'Колонки и примеры'!$B:$B,0)),"") | K105: =IFERROR(INDEX('Колонки и примеры'!K:K,MATCH($B101,'Колонки и примеры'!$B:$B,0)),"") | L105: =IFERROR(INDEX('Колонки и примеры'!L:L,MATCH($B101,'Колонки и примеры'!$B:$B,0)),"")
C106: =IFERROR(INDEX('Колонки и примеры'!C:C,MATCH($B101,'Колонки и примеры'!$B:$B,0)),"") | D106: =IFERROR(INDEX('Колонки и примеры'!D:D,MATCH($B101,'Колонки и примеры'!$B:$B,0)),"") | E106: =IFERROR(INDEX('Колонки и примеры'!E:E,MATCH($B101,'Колонки и примеры'!$B:$B,0)),"") | F106: =IFERROR(INDEX('Колонки и примеры'!F:F,MATCH($B101,'Колонки и примеры'!$B:$B,0)),"") | G106: =IFERROR(INDEX('Колонки и примеры'!G:G,MATCH($B101,'Колонки и примеры'!$B:$B,0)),"") | H106: =IFERROR(INDEX('Колонки и примеры'!H:H,MATCH($B101,'Колонки и примеры'!$B:$B,0)),"") | I106: =IFERROR(INDEX('Колонки и примеры'!I:I,MATCH($B101,'Колонки и примеры'!$B:$B,0)),"") | J106: =IFERROR(INDEX('Колонки и примеры'!J:J,MATCH($B101,'Колонки и примеры'!$B:$B,0)),"") | K106: =IFERROR(INDEX('Колонки и примеры'!K:K,MATCH($B101,'Колонки и примеры'!$B:$B,0)),"") | L106: =IFERROR(INDEX('Колонки и примеры'!L:L,MATCH($B101,'Колонки и примеры'!$B:$B,0)),"")
C107: =IFERROR(INDEX('Колонки и примеры'!C:C,MATCH($B101,'Колонки и примеры'!$B:$B,0)),"") | D107: =IFERROR(INDEX('Колонки и примеры'!D:D,MATCH($B101,'Колонки и примеры'!$B:$B,0)),"") | E107: =IFERROR(INDEX('Колонки и примеры'!E:E,MATCH($B101,'Колонки и примеры'!$B:$B,0)),"") | F107: =IFERROR(INDEX('Колонки и примеры'!F:F,MATCH($B101,'Колонки и примеры'!$B:$B,0)),"") | G107: =IFERROR(INDEX('Колонки и примеры'!G:G,MATCH($B101,'Колонки и примеры'!$B:$B,0)),"") | H107: =IFERROR(INDEX('Колонки и примеры'!H:H,MATCH($B101,'Колонки и примеры'!$B:$B,0)),"") | I107: =IFERROR(INDEX('Колонки и примеры'!I:I,MATCH($B101,'Колонки и примеры'!$B:$B,0)),"") | J107: =IFERROR(INDEX('Колонки и примеры'!J:J,MATCH($B101,'Колонки и примеры'!$B:$B,0)),"") | K107: =IFERROR(INDEX('Колонки и примеры'!K:K,MATCH($B101,'Колонки и примеры'!$B:$B,0)),"") | L107: =IFERROR(INDEX('Колонки и примеры'!L:L,MATCH($B101,'Колонки и примеры'!$B:$B,0)),"")
C108: =IFERROR(INDEX('Колонки и примеры'!C:C,MATCH($B101,'Колонки и примеры'!$B:$B,0)),"") | D108: =IFERROR(INDEX('Колонки и примеры'!D:D,MATCH($B101,'Колонки и примеры'!$B:$B,0)),"") | E108: =IFERROR(INDEX('Колонки и примеры'!E:E,MATCH($B101,'Колонки и примеры'!$B:$B,0)),"") | F108: =IFERROR(INDEX('Колонки и примеры'!F:F,MATCH($B101,'Колонки и примеры'!$B:$B,0)),"") | G108: =IFERROR(INDEX('Колонки и примеры'!G:G,MATCH($B101,'Колонки и примеры'!$B:$B,0)),"") | H108: =IFERROR(INDEX('Колонки и примеры'!H:H,MATCH($B101,'Колонки и примеры'!$B:$B,0)),"") | I108: =IFERROR(INDEX('Колонки и примеры'!I:I,MATCH($B101,'Колонки и примеры'!$B:$B,0)),"") | J108: =IFERROR(INDEX('Колонки и примеры'!J:J,MATCH($B101,'Колонки и примеры'!$B:$B,0)),"") | K108: =IFERROR(INDEX('Колонки и примеры'!K:K,MATCH($B101,'Колонки и примеры'!$B:$B,0)),"") | L108: =IFERROR(INDEX('Колонки и примеры'!L:L,MATCH($B101,'Колонки и примеры'!$B:$B,0)),"")
C109: =IFERROR(INDEX('Колонки и примеры'!C:C,MATCH($B101,'Колонки и примеры'!$B:$B,0)),"") | D109: =IFERROR(INDEX('Колонки и примеры'!D:D,MATCH($B101,'Колонки и примеры'!$B:$B,0)),"") | E109: =IFERROR(INDEX('Колонки и примеры'!E:E,MATCH($B101,'Колонки и примеры'!$B:$B,0)),"") | F109: =IFERROR(INDEX('Колонки и примеры'!F:F,MATCH($B101,'Колонки и примеры'!$B:$B,0)),"") | G109: =IFERROR(INDEX('Колонки и примеры'!G:G,MATCH($B101,'Колонки и примеры'!$B:$B,0)),"") | H109: =IFERROR(INDEX('Колонки и примеры'!H:H,MATCH($B101,'Колонки и примеры'!$B:$B,0)),"") | I109: =IFERROR(INDEX('Колонки и примеры'!I:I,MATCH($B101,'Колонки и примеры'!$B:$B,0)),"") | J109: =IFERROR(INDEX('Колонки и примеры'!J:J,MATCH($B101,'Колонки и примеры'!$B:$B,0)),"") | K109: =IFERROR(INDEX('Колонки и примеры'!K:K,MATCH($B101,'Колонки и примеры'!$B:$B,0)),"") | L109: =IFERROR(INDEX('Колонки и примеры'!L:L,MATCH($B101,'Колонки и примеры'!$B:$B,0)),"")
C110: =IFERROR(INDEX('Колонки и примеры'!C:C,MATCH($B101,'Колонки и примеры'!$B:$B,0)),"") | D110: =IFERROR(INDEX('Колонки и примеры'!D:D,MATCH($B101,'Колонки и примеры'!$B:$B,0)),"") | E110: =IFERROR(INDEX('Колонки и примеры'!E:E,MATCH($B101,'Колонки и примеры'!$B:$B,0)),"") | F110: =IFERROR(INDEX('Колонки и примеры'!F:F,MATCH($B101,'Колонки и примеры'!$B:$B,0)),"") | G110: =IFERROR(INDEX('Колонки и примеры'!G:G,MATCH($B101,'Колонки и примеры'!$B:$B,0)),"") | H110: =IFERROR(INDEX('Колонки и примеры'!H:H,MATCH($B101,'Колонки и примеры'!$B:$B,0)),"") | I110: =IFERROR(INDEX('Колонки и примеры'!I:I,MATCH($B101,'Колонки и примеры'!$B:$B,0)),"") | J110: =IFERROR(INDEX('Колонки и примеры'!J:J,MATCH($B101,'Колонки и примеры'!$B:$B,0)),"") | K110: =IFERROR(INDEX('Колонки и примеры'!K:K,MATCH($B101,'Колонки и примеры'!$B:$B,0)),"") | L110: =IFERROR(INDEX('Колонки и примеры'!L:L,MATCH($B101,'Колонки и примеры'!$B:$B,0)),"")
C111: =IFERROR(INDEX('Колонки и примеры'!C:C,MATCH($B101,'Колонки и примеры'!$B:$B,0)),"") | D111: =IFERROR(INDEX('Колонки и примеры'!D:D,MATCH($B101,'Колонки и примеры'!$B:$B,0)),"") | E111: =IFERROR(INDEX('Колонки и примеры'!E:E,MATCH($B101,'Колонки и примеры'!$B:$B,0)),"") | F111: =IFERROR(INDEX('Колонки и примеры'!F:F,MATCH($B101,'Колонки и примеры'!$B:$B,0)),"") | G111: =IFERROR(INDEX('Колонки и примеры'!G:G,MATCH($B101,'Колонки и примеры'!$B:$B,0)),"") | H111: =IFERROR(INDEX('Колонки и примеры'!H:H,MATCH($B101,'Колонки и примеры'!$B:$B,0)),"") | I111: =IFERROR(INDEX('Колонки и примеры'!I:I,MATCH($B101,'Колонки и примеры'!$B:$B,0)),"") | J111: =IFERROR(INDEX('Колонки и примеры'!J:J,MATCH($B101,'Колонки и примеры'!$B:$B,0)),"") | K111: =IFERROR(INDEX('Колонки и примеры'!K:K,MATCH($B101,'Колонки и примеры'!$B:$B,0)),"") | L111: =IFERROR(INDEX('Колонки и примеры'!L:L,MATCH($B101,'Колонки и примеры'!$B:$B,0)),"")
C112: =IFERROR(INDEX('Колонки и примеры'!C:C,MATCH($B101,'Колонки и примеры'!$B:$B,0)),"") | D112: =IFERROR(INDEX('Колонки и примеры'!D:D,MATCH($B101,'Колонки и примеры'!$B:$B,0)),"") | E112: =IFERROR(INDEX('Колонки и примеры'!E:E,MATCH($B101,'Колонки и примеры'!$B:$B,0)),"") | F112: =IFERROR(INDEX('Колонки и примеры'!F:F,MATCH($B101,'Колонки и примеры'!$B:$B,0)),"") | G112: =IFERROR(INDEX('Колонки и примеры'!G:G,MATCH($B101,'Колонки и примеры'!$B:$B,0)),"") | H112: =IFERROR(INDEX('Колонки и примеры'!H:H,MATCH($B101,'Колонки и примеры'!$B:$B,0)),"") | I112: =IFERROR(INDEX('Колонки и примеры'!I:I,MATCH($B101,'Колонки и примеры'!$B:$B,0)),"") | J112: =IFERROR(INDEX('Колонки и примеры'!J:J,MATCH($B101,'Колонки и примеры'!$B:$B,0)),"") | K112: =IFERROR(INDEX('Колонки и примеры'!K:K,MATCH($B101,'Колонки и примеры'!$B:$B,0)),"") | L112: =IFERROR(INDEX('Колонки и примеры'!L:L,MATCH($B101,'Колонки и примеры'!$B:$B,0)),"")
C113: =IFERROR(INDEX('Колонки и примеры'!C:C,MATCH($B101,'Колонки и примеры'!$B:$B,0)),"") | D113: =IFERROR(INDEX('Колонки и примеры'!D:D,MATCH($B101,'Колонки и примеры'!$B:$B,0)),"") | E113: =IFERROR(INDEX('Колонки и примеры'!E:E,MATCH($B101,'Колонки и примеры'!$B:$B,0)),"") | F113: =IFERROR(INDEX('Колонки и примеры'!F:F,MATCH($B101,'Колонки и примеры'!$B:$B,0)),"") | G113: =IFERROR(INDEX('Колонки и примеры'!G:G,MATCH($B101,'Колонки и примеры'!$B:$B,0)),"") | H113: =IFERROR(INDEX('Колонки и примеры'!H:H,MATCH($B101,'Колонки и примеры'!$B:$B,0)),"") | I113: =IFERROR(INDEX('Колонки и примеры'!I:I,MATCH($B101,'Колонки и примеры'!$B:$B,0)),"") | J113: =IFERROR(INDEX('Колонки и примеры'!J:J,MATCH($B101,'Колонки и примеры'!$B:$B,0)),"") | K113: =IFERROR(INDEX('Колонки и примеры'!K:K,MATCH($B101,'Колонки и примеры'!$B:$B,0)),"") | L113: =IFERROR(INDEX('Колонки и примеры'!L:L,MATCH($B101,'Колонки и примеры'!$B:$B,0)),"")
C114: =IFERROR(INDEX('Колонки и примеры'!C:C,MATCH($B101,'Колонки и примеры'!$B:$B,0)),"") | D114: =IFERROR(INDEX('Колонки и примеры'!D:D,MATCH($B101,'Колонки и примеры'!$B:$B,0)),"") | E114: =IFERROR(INDEX('Колонки и примеры'!E:E,MATCH($B101,'Колонки и примеры'!$B:$B,0)),"") | F114: =IFERROR(INDEX('Колонки и примеры'!F:F,MATCH($B101,'Колонки и примеры'!$B:$B,0)),"") | G114: =IFERROR(INDEX('Колонки и примеры'!G:G,MATCH($B101,'Колонки и примеры'!$B:$B,0)),"") | H114: =IFERROR(INDEX('Колонки и примеры'!H:H,MATCH($B101,'Колонки и примеры'!$B:$B,0)),"") | I114: =IFERROR(INDEX('Колонки и примеры'!I:I,MATCH($B101,'Колонки и примеры'!$B:$B,0)),"") | J114: =IFERROR(INDEX('Колонки и примеры'!J:J,MATCH($B101,'Колонки и примеры'!$B:$B,0)),"") | K114: =IFERROR(INDEX('Колонки и примеры'!K:K,MATCH($B101,'Колонки и примеры'!$B:$B,0)),"") | L114: =IFERROR(INDEX('Колонки и примеры'!L:L,MATCH($B101,'Колонки и примеры'!$B:$B,0)),"")
C115: =IFERROR(INDEX('Колонки и примеры'!C:C,MATCH($B101,'Колонки и примеры'!$B:$B,0)),"") | D115: =IFERROR(INDEX('Колонки и примеры'!D:D,MATCH($B101,'Колонки и примеры'!$B:$B,0)),"") | E115: =IFERROR(INDEX('Колонки и примеры'!E:E,MATCH($B101,'Колонки и примеры'!$B:$B,0)),"") | F115: =IFERROR(INDEX('Колонки и примеры'!F:F,MATCH($B101,'Колонки и примеры'!$B:$B,0)),"") | G115: =IFERROR(INDEX('Колонки и примеры'!G:G,MATCH($B101,'Колонки и примеры'!$B:$B,0)),"") | H115: =IFERROR(INDEX('Колонки и примеры'!H:H,MATCH($B101,'Колонки и примеры'!$B:$B,0)),"") | I115: =IFERROR(INDEX('Колонки и примеры'!I:I,MATCH($B101,'Колонки и примеры'!$B:$B,0)),"") | J115: =IFERROR(INDEX('Колонки и примеры'!J:J,MATCH($B101,'Колонки и примеры'!$B:$B,0)),"") | K115: =IFERROR(INDEX('Колонки и примеры'!K:K,MATCH($B101,'Колонки и примеры'!$B:$B,0)),"") | L115: =IFERROR(INDEX('Колонки и примеры'!L:L,MATCH($B101,'Колонки и примеры'!$B:$B,0)),"")
C116: =IFERROR(INDEX('Колонки и примеры'!C:C,MATCH($B101,'Колонки и примеры'!$B:$B,0)),"") | D116: =IFERROR(INDEX('Колонки и примеры'!D:D,MATCH($B101,'Колонки и примеры'!$B:$B,0)),"") | E116: =IFERROR(INDEX('Колонки и примеры'!E:E,MATCH($B101,'Колонки и примеры'!$B:$B,0)),"") | F116: =IFERROR(INDEX('Колонки и примеры'!F:F,MATCH($B101,'Колонки и примеры'!$B:$B,0)),"") | G116: =IFERROR(INDEX('Колонки и примеры'!G:G,MATCH($B101,'Колонки и примеры'!$B:$B,0)),"") | H116: =IFERROR(INDEX('Колонки и примеры'!H:H,MATCH($B101,'Колонки и примеры'!$B:$B,0)),"") | I116: =IFERROR(INDEX('Колонки и примеры'!I:I,MATCH($B101,'Колонки и примеры'!$B:$B,0)),"") | J116: =IFERROR(INDEX('Колонки и примеры'!J:J,MATCH($B101,'Колонки и примеры'!$B:$B,0)),"") | K116: =IFERROR(INDEX('Колонки и примеры'!K:K,MATCH($B101,'Колонки и примеры'!$B:$B,0)),"") | L116: =IFERROR(INDEX('Колонки и примеры'!L:L,MATCH($B101,'Колонки и примеры'!$B:$B,0)),"")
C117: =IFERROR(INDEX('Колонки и примеры'!C:C,MATCH($B101,'Колонки и примеры'!$B:$B,0)),"") | D117: =IFERROR(INDEX('Колонки и примеры'!D:D,MATCH($B101,'Колонки и примеры'!$B:$B,0)),"") | E117: =IFERROR(INDEX('Колонки и примеры'!E:E,MATCH($B101,'Колонки и примеры'!$B:$B,0)),"") | F117: =IFERROR(INDEX('Колонки и примеры'!F:F,MATCH($B101,'Колонки и примеры'!$B:$B,0)),"") | G117: =IFERROR(INDEX('Колонки и примеры'!G:G,MATCH($B101,'Колонки и примеры'!$B:$B,0)),"") | H117: =IFERROR(INDEX('Колонки и примеры'!H:H,MATCH($B101,'Колонки и примеры'!$B:$B,0)),"") | I117: =IFERROR(INDEX('Колонки и примеры'!I:I,MATCH($B101,'Колонки и примеры'!$B:$B,0)),"") | J117: =IFERROR(INDEX('Колонки и примеры'!J:J,MATCH($B101,'Колонки и примеры'!$B:$B,0)),"") | K117: =IFERROR(INDEX('Колонки и примеры'!K:K,MATCH($B101,'Колонки и примеры'!$B:$B,0)),"") | L117: =IFERROR(INDEX('Колонки и примеры'!L:L,MATCH($B101,'Колонки и примеры'!$B:$B,0)),"")
C118: =IFERROR(INDEX('Колонки и примеры'!C:C,MATCH($B101,'Колонки и примеры'!$B:$B,0)),"") | D118: =IFERROR(INDEX('Колонки и примеры'!D:D,MATCH($B101,'Колонки и примеры'!$B:$B,0)),"") | E118: =IFERROR(INDEX('Колонки и примеры'!E:E,MATCH($B101,'Колонки и примеры'!$B:$B,0)),"") | F118: =IFERROR(INDEX('Колонки и примеры'!F:F,MATCH($B101,'Колонки и примеры'!$B:$B,0)),"") | G118: =IFERROR(INDEX('Колонки и примеры'!G:G,MATCH($B101,'Колонки и примеры'!$B:$B,0)),"") | H118: =IFERROR(INDEX('Колонки и примеры'!H:H,MATCH($B101,'Колонки и примеры'!$B:$B,0)),"") | I118: =IFERROR(INDEX('Колонки и примеры'!I:I,MATCH($B101,'Колонки и примеры'!$B:$B,0)),"") | J118: =IFERROR(INDEX('Колонки и примеры'!J:J,MATCH($B101,'Колонки и примеры'!$B:$B,0)),"") | K118: =IFERROR(INDEX('Колонки и примеры'!K:K,MATCH($B101,'Колонки и примеры'!$B:$B,0)),"") | L118: =IFERROR(INDEX('Колонки и примеры'!L:L,MATCH($B101,'Колонки и примеры'!$B:$B,0)),"")
C119: =IFERROR(INDEX('Колонки и примеры'!C:C,MATCH($B101,'Колонки и примеры'!$B:$B,0)),"") | D119: =IFERROR(INDEX('Колонки и примеры'!D:D,MATCH($B101,'Колонки и примеры'!$B:$B,0)),"") | E119: =IFERROR(INDEX('Колонки и примеры'!E:E,MATCH($B101,'Колонки и примеры'!$B:$B,0)),"") | F119: =IFERROR(INDEX('Колонки и примеры'!F:F,MATCH($B101,'Колонки и примеры'!$B:$B,0)),"") | G119: =IFERROR(INDEX('Колонки и примеры'!G:G,MATCH($B101,'Колонки и примеры'!$B:$B,0)),"") | H119: =IFERROR(INDEX('Колонки и примеры'!H:H,MATCH($B101,'Колонки и примеры'!$B:$B,0)),"") | I119: =IFERROR(INDEX('Колонки и примеры'!I:I,MATCH($B101,'Колонки и примеры'!$B:$B,0)),"") | J119: =IFERROR(INDEX('Колонки и примеры'!J:J,MATCH($B101,'Колонки и примеры'!$B:$B,0)),"") | K119: =IFERROR(INDEX('Колонки и примеры'!K:K,MATCH($B101,'Колонки и примеры'!$B:$B,0)),"") | L119: =IFERROR(INDEX('Колонки и примеры'!L:L,MATCH($B101,'Колонки и примеры'!$B:$B,0)),"")
C120: =IFERROR(INDEX('Колонки и примеры'!C:C,MATCH($B101,'Колонки и примеры'!$B:$B,0)),"") | D120: =IFERROR(INDEX('Колонки и примеры'!D:D,MATCH($B101,'Колонки и примеры'!$B:$B,0)),"") | E120: =IFERROR(INDEX('Колонки и примеры'!E:E,MATCH($B101,'Колонки и примеры'!$B:$B,0)),"") | F120: =IFERROR(INDEX('Колонки и примеры'!F:F,MATCH($B101,'Колонки и примеры'!$B:$B,0)),"") | G120: =IFERROR(INDEX('Колонки и примеры'!G:G,MATCH($B101,'Колонки и примеры'!$B:$B,0)),"") | H120: =IFERROR(INDEX('Колонки и примеры'!H:H,MATCH($B101,'Колонки и примеры'!$B:$B,0)),"") | I120: =IFERROR(INDEX('Колонки и примеры'!I:I,MATCH($B101,'Колонки и примеры'!$B:$B,0)),"") | J120: =IFERROR(INDEX('Колонки и примеры'!J:J,MATCH($B101,'Колонки и примеры'!$B:$B,0)),"") | K120: =IFERROR(INDEX('Колонки и примеры'!K:K,MATCH($B101,'Колонки и примеры'!$B:$B,0)),"") | L120: =IFERROR(INDEX('Колонки и примеры'!L:L,MATCH($B101,'Колонки и примеры'!$B:$B,0)),"")
C121: =IFERROR(INDEX('Колонки и примеры'!C:C,MATCH($B101,'Колонки и примеры'!$B:$B,0)),"") | D121: =IFERROR(INDEX('Колонки и примеры'!D:D,MATCH($B101,'Колонки и примеры'!$B:$B,0)),"") | E121: =IFERROR(INDEX('Колонки и примеры'!E:E,MATCH($B101,'Колонки и примеры'!$B:$B,0)),"") | F121: =IFERROR(INDEX('Колонки и примеры'!F:F,MATCH($B101,'Колонки и примеры'!$B:$B,0)),"") | G121: =IFERROR(INDEX('Колонки и примеры'!G:G,MATCH($B101,'Колонки и примеры'!$B:$B,0)),"") | H121: =IFERROR(INDEX('Колонки и примеры'!H:H,MATCH($B101,'Колонки и примеры'!$B:$B,0)),"") | I121: =IFERROR(INDEX('Колонки и примеры'!I:I,MATCH($B101,'Колонки и примеры'!$B:$B,0)),"") | J121: =IFERROR(INDEX('Колонки и примеры'!J:J,MATCH($B101,'Колонки и примеры'!$B:$B,0)),"") | K121: =IFERROR(INDEX('Колонки и примеры'!K:K,MATCH($B101,'Колонки и примеры'!$B:$B,0)),"") | L121: =IFERROR(INDEX('Колонки и примеры'!L:L,MATCH($B101,'Колонки и примеры'!$B:$B,0)),"")
C122: =IFERROR(INDEX('Колонки и примеры'!C:C,MATCH($B101,'Колонки и примеры'!$B:$B,0)),"") | D122: =IFERROR(INDEX('Колонки и примеры'!D:D,MATCH($B101,'Колонки и примеры'!$B:$B,0)),"") | E122: =IFERROR(INDEX('Колонки и примеры'!E:E,MATCH($B101,'Колонки и примеры'!$B:$B,0)),"") | F122: =IFERROR(INDEX('Колонки и примеры'!F:F,MATCH($B101,'Колонки и примеры'!$B:$B,0)),"") | G122: =IFERROR(INDEX('Колонки и примеры'!G:G,MATCH($B101,'Колонки и примеры'!$B:$B,0)),"") | H122: =IFERROR(INDEX('Колонки и примеры'!H:H,MATCH($B101,'Колонки и примеры'!$B:$B,0)),"") | I122: =IFERROR(INDEX('Колонки и примеры'!I:I,MATCH($B101,'Колонки и примеры'!$B:$B,0)),"") | J122: =IFERROR(INDEX('Колонки и примеры'!J:J,MATCH($B101,'Колонки и примеры'!$B:$B,0)),"") | K122: =IFERROR(INDEX('Колонки и примеры'!K:K,MATCH($B101,'Колонки и примеры'!$B:$B,0)),"") | L122: =IFERROR(INDEX('Колонки и примеры'!L:L,MATCH($B101,'Колонки и примеры'!$B:$B,0)),"")
C123: =IFERROR(INDEX('Колонки и примеры'!C:C,MATCH($B101,'Колонки и примеры'!$B:$B,0)),"") | D123: =IFERROR(INDEX('Колонки и примеры'!D:D,MATCH($B101,'Колонки и примеры'!$B:$B,0)),"") | E123: =IFERROR(INDEX('Колонки и примеры'!E:E,MATCH($B101,'Колонки и примеры'!$B:$B,0)),"") | F123: =IFERROR(INDEX('Колонки и примеры'!F:F,MATCH($B101,'Колонки и примеры'!$B:$B,0)),"") | G123: =IFERROR(INDEX('Колонки и примеры'!G:G,MATCH($B101,'Колонки и примеры'!$B:$B,0)),"") | H123: =IFERROR(INDEX('Колонки и примеры'!H:H,MATCH($B101,'Колонки и примеры'!$B:$B,0)),"") | I123: =IFERROR(INDEX('Колонки и примеры'!I:I,MATCH($B101,'Колонки и примеры'!$B:$B,0)),"") | J123: =IFERROR(INDEX('Колонки и примеры'!J:J,MATCH($B101,'Колонки и примеры'!$B:$B,0)),"") | K123: =IFERROR(INDEX('Колонки и примеры'!K:K,MATCH($B101,'Колонки и примеры'!$B:$B,0)),"") | L123: =IFERROR(INDEX('Колонки и примеры'!L:L,MATCH($B101,'Колонки и примеры'!$B:$B,0)),"")
C124: =IFERROR(INDEX('Колонки и примеры'!C:C,MATCH($B101,'Колонки и примеры'!$B:$B,0)),"") | D124: =IFERROR(INDEX('Колонки и примеры'!D:D,MATCH($B101,'Колонки и примеры'!$B:$B,0)),"") | E124: =IFERROR(INDEX('Колонки и примеры'!E:E,MATCH($B101,'Колонки и примеры'!$B:$B,0)),"") | F124: =IFERROR(INDEX('Колонки и примеры'!F:F,MATCH($B101,'Колонки и примеры'!$B:$B,0)),"") | G124: =IFERROR(INDEX('Колонки и примеры'!G:G,MATCH($B101,'Колонки и примеры'!$B:$B,0)),"") | H124: =IFERROR(INDEX('Колонки и примеры'!H:H,MATCH($B101,'Колонки и примеры'!$B:$B,0)),"") | I124: =IFERROR(INDEX('Колонки и примеры'!I:I,MATCH($B101,'Колонки и примеры'!$B:$B,0)),"") | J124: =IFERROR(INDEX('Колонки и примеры'!J:J,MATCH($B101,'Колонки и примеры'!$B:$B,0)),"") | K124: =IFERROR(INDEX('Колонки и примеры'!K:K,MATCH($B101,'Колонки и примеры'!$B:$B,0)),"") | L124: =IFERROR(INDEX('Колонки и примеры'!L:L,MATCH($B101,'Колонки и примеры'!$B:$B,0)),"")
...

Sheet index
A1: id | B1: type | C1: ukr | D1: rus | E1: eng | F1: ger | G1: ukr_sub | H1: rus_sub | I1: eng_sub | J1: ger_sub | K1: href | L1: meta
A2: 1 | B2: heroImage | C2: =IFERROR(INDEX('Колонки и примеры'!C:C,MATCH($B2,'Колонки и примеры'!$B:$B,0)),"") -> images/hero.jpg | D2: =IFERROR(INDEX('Колонки и примеры'!D:D,MATCH($B2,'Колонки и примеры'!$B:$B,0)),"") -> images/hero.jpg | E2: =IFERROR(INDEX('Колонки и примеры'!E:E,MATCH($B2,'Колонки и примеры'!$B:$B,0)),"") -> images/hero.jpg | F2: =IFERROR(INDEX('Колонки и примеры'!F:F,MATCH($B2,'Колонки и примеры'!$B:$B,0)),"") -> images/hero.jpg | G2: =IFERROR(INDEX('Колонки и примеры'!G:G,MATCH($B2,'Колонки и примеры'!$B:$B,0)),"") -> 0 | H2: =IFERROR(INDEX('Колонки и примеры'!H:H,MATCH($B2,'Колонки и примеры'!$B:$B,0)),"") -> 0 | I2: =IFERROR(INDEX('Колонки и примеры'!I:I,MATCH($B2,'Колонки и примеры'!$B:$B,0)),"") -> 0 | J2: =IFERROR(INDEX('Колонки и примеры'!J:J,MATCH($B2,'Колонки и примеры'!$B:$B,0)),"") -> 0 | K2: =IFERROR(INDEX('Колонки и примеры'!K:K,MATCH($B2,'Колонки и примеры'!$B:$B,0)),"") -> 0 | L2: =IFERROR(INDEX('Колонки и примеры'!L:L,MATCH($B2,'Колонки и примеры'!$B:$B,0)),"") -> w=1200;h=520;resizeMode=cover | N2: 1. Выберите type из выпадающего списка
A3: 2 | B3: eyebrow | C3: =IFERROR(INDEX('Колонки и примеры'!C:C,MATCH($B3,'Колонки и примеры'!$B:$B,0)),"") -> Академія краси | D3: =IFERROR(INDEX('Колонки и примеры'!D:D,MATCH($B3,'Колонки и примеры'!$B:$B,0)),"") -> Академия красоты | E3: =IFERROR(INDEX('Колонки и примеры'!E:E,MATCH($B3,'Колонки и примеры'!$B:$B,0)),"") -> Beauty Academy | F3: =IFERROR(INDEX('Колонки и примеры'!F:F,MATCH($B3,'Колонки и примеры'!$B:$B,0)),"") -> Beauty Academy | G3: =IFERROR(INDEX('Колонки и примеры'!G:G,MATCH($B3,'Колонки и примеры'!$B:$B,0)),"") -> 0 | H3: =IFERROR(INDEX('Колонки и примеры'!H:H,MATCH($B3,'Колонки и примеры'!$B:$B,0)),"") -> 0 | I3: =IFERROR(INDEX('Колонки и примеры'!I:I,MATCH($B3,'Колонки и примеры'!$B:$B,0)),"") -> 0 | J3: =IFERROR(INDEX('Колонки и примеры'!J:J,MATCH($B3,'Колонки и примеры'!$B:$B,0)),"") -> 0 | K3: =IFERROR(INDEX('Колонки и примеры'!K:K,MATCH($B3,'Колонки и примеры'!$B:$B,0)),"") -> 0 | L3: =IFERROR(INDEX('Колонки и примеры'!L:L,MATCH($B3,'Колонки и примеры'!$B:$B,0)),"") -> 0 | N3: 2. Пример автоматически подтянется
A4: 3 | B4: title | C4: =IFERROR(INDEX('Колонки и примеры'!C:C,MATCH($B4,'Колонки и примеры'!$B:$B,0)),"") -> Майстерність перманентного макіяжу | D4: =IFERROR(INDEX('Колонки и примеры'!D:D,MATCH($B4,'Колонки и примеры'!$B:$B,0)),"") -> Мастерство перманентного макияжа | E4: =IFERROR(INDEX('Колонки и примеры'!E:E,MATCH($B4,'Колонки и примеры'!$B:$B,0)),"") -> Master permanent makeup | F4: =IFERROR(INDEX('Колонки и примеры'!F:F,MATCH($B4,'Колонки и примеры'!$B:$B,0)),"") -> Meister der Permanent Make-up | G4: =IFERROR(INDEX('Колонки и примеры'!G:G,MATCH($B4,'Колонки и примеры'!$B:$B,0)),"") -> 0 | H4: =IFERROR(INDEX('Колонки и примеры'!H:H,MATCH($B4,'Колонки и примеры'!$B:$B,0)),"") -> 0 | I4: =IFERROR(INDEX('Колонки и примеры'!I:I,MATCH($B4,'Колонки и примеры'!$B:$B,0)),"") -> 0 | J4: =IFERROR(INDEX('Колонки и примеры'!J:J,MATCH($B4,'Колонки и примеры'!$B:$B,0)),"") -> 0 | K4: =IFERROR(INDEX('Колонки и примеры'!K:K,MATCH($B4,'Колонки и примеры'!$B:$B,0)),"") -> 0 | L4: =IFERROR(INDEX('Колонки и примеры'!L:L,MATCH($B4,'Колонки и примеры'!$B:$B,0)),"") -> 0 | N4: 3. Замените пример своим текстом
A5: 4 | B5: subtitle | C5: =IFERROR(INDEX('Колонки и примеры'!C:C,MATCH($B5,'Колонки и примеры'!$B:$B,0)),"") -> Навчайтеся у найкращих практиків | D5: =IFERROR(INDEX('Колонки и примеры'!D:D,MATCH($B5,'Колонки и примеры'!$B:$B,0)),"") -> Учитесь у лучших практиков | E5: =IFERROR(INDEX('Колонки и примеры'!E:E,MATCH($B5,'Колонки и примеры'!$B:$B,0)),"") -> Learn from top professionals | F5: =IFERROR(INDEX('Колонки и примеры'!F:F,MATCH($B5,'Колонки и примеры'!$B:$B,0)),"") -> Lernen Sie von den besten Profis | G5: =IFERROR(INDEX('Колонки и примеры'!G:G,MATCH($B5,'Колонки и примеры'!$B:$B,0)),"") -> 0 | H5: =IFERROR(INDEX('Колонки и примеры'!H:H,MATCH($B5,'Колонки и примеры'!$B:$B,0)),"") -> 0 | I5: =IFERROR(INDEX('Колонки и примеры'!I:I,MATCH($B5,'Колонки и примеры'!$B:$B,0)),"") -> 0 | J5: =IFERROR(INDEX('Колонки и примеры'!J:J,MATCH($B5,'Колонки и примеры'!$B:$B,0)),"") -> 0 | K5: =IFERROR(INDEX('Колонки и примеры'!K:K,MATCH($B5,'Колонки и примеры'!$B:$B,0)),"") -> 0 | L5: =IFERROR(INDEX('Колонки и примеры'!L:L,MATCH($B5,'Колонки и примеры'!$B:$B,0)),"") -> 0
A6: 6 | B6: card | C6: =IFERROR(INDEX('Колонки и примеры'!C:C,MATCH($B6,'Колонки и примеры'!$B:$B,0)),"") -> Заголовок карточки | D6: =IFERROR(INDEX('Колонки и примеры'!D:D,MATCH($B6,'Колонки и примеры'!$B:$B,0)),"") -> Заголовок карточки | E6: =IFERROR(INDEX('Колонки и примеры'!E:E,MATCH($B6,'Колонки и примеры'!$B:$B,0)),"") -> Card title | F6: =IFERROR(INDEX('Колонки и примеры'!F:F,MATCH($B6,'Колонки и примеры'!$B:$B,0)),"") -> Kartenüberschrift | G6: =IFERROR(INDEX('Колонки и примеры'!G:G,MATCH($B6,'Колонки и примеры'!$B:$B,0)),"") -> Опис карточки українською | H6: =IFERROR(INDEX('Колонки и примеры'!H:H,MATCH($B6,'Колонки и примеры'!$B:$B,0)),"") -> Описание карточки на русском | I6: =IFERROR(INDEX('Колонки и примеры'!I:I,MATCH($B6,'Колонки и примеры'!$B:$B,0)),"") -> Card description in English | J6: =IFERROR(INDEX('Колонки и примеры'!J:J,MATCH($B6,'Колонки и примеры'!$B:$B,0)),"") -> Kartenbeschreibung auf Deutsch | K6: /skin | L6: =IFERROR(INDEX('Колонки и примеры'!L:L,MATCH($B6,'Колонки и примеры'!$B:$B,0)),"") -> 0
A7: 7 | B7: card | C7: =IFERROR(INDEX('Колонки и примеры'!C:C,MATCH($B7,'Колонки и примеры'!$B:$B,0)),"") -> Заголовок карточки | D7: =IFERROR(INDEX('Колонки и примеры'!D:D,MATCH($B7,'Колонки и примеры'!$B:$B,0)),"") -> Заголовок карточки | E7: =IFERROR(INDEX('Колонки и примеры'!E:E,MATCH($B7,'Колонки и примеры'!$B:$B,0)),"") -> Card title | F7: =IFERROR(INDEX('Колонки и примеры'!F:F,MATCH($B7,'Колонки и примеры'!$B:$B,0)),"") -> Kartenüberschrift | G7: =IFERROR(INDEX('Колонки и примеры'!G:G,MATCH($B7,'Колонки и примеры'!$B:$B,0)),"") -> Опис карточки українською | H7: =IFERROR(INDEX('Колонки и примеры'!H:H,MATCH($B7,'Колонки и примеры'!$B:$B,0)),"") -> Описание карточки на русском | I7: =IFERROR(INDEX('Колонки и примеры'!I:I,MATCH($B7,'Колонки и примеры'!$B:$B,0)),"") -> Card description in English | J7: =IFERROR(INDEX('Колонки и примеры'!J:J,MATCH($B7,'Колонки и примеры'!$B:$B,0)),"") -> Kartenbeschreibung auf Deutsch | K7: /skin | L7: =IFERROR(INDEX('Колонки и примеры'!L:L,MATCH($B7,'Колонки и примеры'!$B:$B,0)),"") -> 0
A8: 8 | B8: card | C8: =IFERROR(INDEX('Колонки и примеры'!C:C,MATCH($B8,'Колонки и примеры'!$B:$B,0)),"") -> Заголовок карточки | D8: =IFERROR(INDEX('Колонки и примеры'!D:D,MATCH($B8,'Колонки и примеры'!$B:$B,0)),"") -> Заголовок карточки | E8: =IFERROR(INDEX('Колонки и примеры'!E:E,MATCH($B8,'Колонки и примеры'!$B:$B,0)),"") -> Card title | F8: =IFERROR(INDEX('Колонки и примеры'!F:F,MATCH($B8,'Колонки и примеры'!$B:$B,0)),"") -> Kartenüberschrift | G8: =IFERROR(INDEX('Колонки и примеры'!G:G,MATCH($B8,'Колонки и примеры'!$B:$B,0)),"") -> Опис карточки українською | H8: =IFERROR(INDEX('Колонки и примеры'!H:H,MATCH($B8,'Колонки и примеры'!$B:$B,0)),"") -> Описание карточки на русском | I8: =IFERROR(INDEX('Колонки и примеры'!I:I,MATCH($B8,'Колонки и примеры'!$B:$B,0)),"") -> Card description in English | J8: =IFERROR(INDEX('Колонки и примеры'!J:J,MATCH($B8,'Колонки и примеры'!$B:$B,0)),"") -> Kartenbeschreibung auf Deutsch | K8: /skin | L8: =IFERROR(INDEX('Колонки и примеры'!L:L,MATCH($B8,'Колонки и примеры'!$B:$B,0)),"") -> 0
A9: 9 | B9: card | C9: =IFERROR(INDEX('Колонки и примеры'!C:C,MATCH($B9,'Колонки и примеры'!$B:$B,0)),"") -> Заголовок карточки | D9: =IFERROR(INDEX('Колонки и примеры'!D:D,MATCH($B9,'Колонки и примеры'!$B:$B,0)),"") -> Заголовок карточки | E9: =IFERROR(INDEX('Колонки и примеры'!E:E,MATCH($B9,'Колонки и примеры'!$B:$B,0)),"") -> Card title | F9: =IFERROR(INDEX('Колонки и примеры'!F:F,MATCH($B9,'Колонки и примеры'!$B:$B,0)),"") -> Kartenüberschrift | G9: =IFERROR(INDEX('Колонки и примеры'!G:G,MATCH($B9,'Колонки и примеры'!$B:$B,0)),"") -> Опис карточки українською | H9: =IFERROR(INDEX('Колонки и примеры'!H:H,MATCH($B9,'Колонки и примеры'!$B:$B,0)),"") -> Описание карточки на русском | I9: =IFERROR(INDEX('Колонки и примеры'!I:I,MATCH($B9,'Колонки и примеры'!$B:$B,0)),"") -> Card description in English | J9: =IFERROR(INDEX('Колонки и примеры'!J:J,MATCH($B9,'Колонки и примеры'!$B:$B,0)),"") -> Kartenbeschreibung auf Deutsch | K9: /skin | L9: =IFERROR(INDEX('Колонки и примеры'!L:L,MATCH($B9,'Колонки и примеры'!$B:$B,0)),"") -> 0
A10: 11 | C10: =IFERROR(INDEX('Колонки и примеры'!C:C,MATCH($B10,'Колонки и примеры'!$B:$B,0)),"") | D10: =IFERROR(INDEX('Колонки и примеры'!D:D,MATCH($B10,'Колонки и примеры'!$B:$B,0)),"") | E10: =IFERROR(INDEX('Колонки и примеры'!E:E,MATCH($B10,'Колонки и примеры'!$B:$B,0)),"") | F10: =IFERROR(INDEX('Колонки и примеры'!F:F,MATCH($B10,'Колонки и примеры'!$B:$B,0)),"") | G10: =IFERROR(INDEX('Колонки и примеры'!G:G,MATCH($B10,'Колонки и примеры'!$B:$B,0)),"") | H10: =IFERROR(INDEX('Колонки и примеры'!H:H,MATCH($B10,'Колонки и примеры'!$B:$B,0)),"") | I10: =IFERROR(INDEX('Колонки и примеры'!I:I,MATCH($B10,'Колонки и примеры'!$B:$B,0)),"") | J10: =IFERROR(INDEX('Колонки и примеры'!J:J,MATCH($B10,'Колонки и примеры'!$B:$B,0)),"") | K10: =IFERROR(INDEX('Колонки и примеры'!K:K,MATCH($B10,'Колонки и примеры'!$B:$B,0)),"") | L10: =IFERROR(INDEX('Колонки и примеры'!L:L,MATCH($B10,'Колонки и примеры'!$B:$B,0)),"")
A11: 12 | C11: =IFERROR(INDEX('Колонки и примеры'!C:C,MATCH($B11,'Колонки и примеры'!$B:$B,0)),"") | D11: =IFERROR(INDEX('Колонки и примеры'!D:D,MATCH($B11,'Колонки и примеры'!$B:$B,0)),"") | E11: =IFERROR(INDEX('Колонки и примеры'!E:E,MATCH($B11,'Колонки и примеры'!$B:$B,0)),"") | F11: =IFERROR(INDEX('Колонки и примеры'!F:F,MATCH($B11,'Колонки и примеры'!$B:$B,0)),"") | G11: =IFERROR(INDEX('Колонки и примеры'!G:G,MATCH($B11,'Колонки и примеры'!$B:$B,0)),"") | H11: =IFERROR(INDEX('Колонки и примеры'!H:H,MATCH($B11,'Колонки и примеры'!$B:$B,0)),"") | I11: =IFERROR(INDEX('Колонки и примеры'!I:I,MATCH($B11,'Колонки и примеры'!$B:$B,0)),"") | J11: =IFERROR(INDEX('Колонки и примеры'!J:J,MATCH($B11,'Колонки и примеры'!$B:$B,0)),"") | K11: =IFERROR(INDEX('Колонки и примеры'!K:K,MATCH($B11,'Колонки и примеры'!$B:$B,0)),"") | L11: =IFERROR(INDEX('Колонки и примеры'!L:L,MATCH($B11,'Колонки и примеры'!$B:$B,0)),"")
A12: 13 | C12: =IFERROR(INDEX('Колонки и примеры'!C:C,MATCH($B12,'Колонки и примеры'!$B:$B,0)),"") | D12: =IFERROR(INDEX('Колонки и примеры'!D:D,MATCH($B12,'Колонки и примеры'!$B:$B,0)),"") | E12: =IFERROR(INDEX('Колонки и примеры'!E:E,MATCH($B12,'Колонки и примеры'!$B:$B,0)),"") | F12: =IFERROR(INDEX('Колонки и примеры'!F:F,MATCH($B12,'Колонки и примеры'!$B:$B,0)),"") | G12: =IFERROR(INDEX('Колонки и примеры'!G:G,MATCH($B12,'Колонки и примеры'!$B:$B,0)),"") | H12: =IFERROR(INDEX('Колонки и примеры'!H:H,MATCH($B12,'Колонки и примеры'!$B:$B,0)),"") | I12: =IFERROR(INDEX('Колонки и примеры'!I:I,MATCH($B12,'Колонки и примеры'!$B:$B,0)),"") | J12: =IFERROR(INDEX('Колонки и примеры'!J:J,MATCH($B12,'Колонки и примеры'!$B:$B,0)),"") | K12: =IFERROR(INDEX('Колонки и примеры'!K:K,MATCH($B12,'Колонки и примеры'!$B:$B,0)),"") | L12: =IFERROR(INDEX('Колонки и примеры'!L:L,MATCH($B12,'Колонки и примеры'!$B:$B,0)),"")
A13: 14 | C13: =IFERROR(INDEX('Колонки и примеры'!C:C,MATCH($B13,'Колонки и примеры'!$B:$B,0)),"") | D13: =IFERROR(INDEX('Колонки и примеры'!D:D,MATCH($B13,'Колонки и примеры'!$B:$B,0)),"") | E13: =IFERROR(INDEX('Колонки и примеры'!E:E,MATCH($B13,'Колонки и примеры'!$B:$B,0)),"") | F13: =IFERROR(INDEX('Колонки и примеры'!F:F,MATCH($B13,'Колонки и примеры'!$B:$B,0)),"") | G13: =IFERROR(INDEX('Колонки и примеры'!G:G,MATCH($B13,'Колонки и примеры'!$B:$B,0)),"") | H13: =IFERROR(INDEX('Колонки и примеры'!H:H,MATCH($B13,'Колонки и примеры'!$B:$B,0)),"") | I13: =IFERROR(INDEX('Колонки и примеры'!I:I,MATCH($B13,'Колонки и примеры'!$B:$B,0)),"") | J13: =IFERROR(INDEX('Колонки и примеры'!J:J,MATCH($B13,'Колонки и примеры'!$B:$B,0)),"") | K13: =IFERROR(INDEX('Колонки и примеры'!K:K,MATCH($B13,'Колонки и примеры'!$B:$B,0)),"") | L13: =IFERROR(INDEX('Колонки и примеры'!L:L,MATCH($B13,'Колонки и примеры'!$B:$B,0)),"")
A14: 15 | C14: =IFERROR(INDEX('Колонки и примеры'!C:C,MATCH($B14,'Колонки и примеры'!$B:$B,0)),"") | D14: =IFERROR(INDEX('Колонки и примеры'!D:D,MATCH($B14,'Колонки и примеры'!$B:$B,0)),"") | E14: =IFERROR(INDEX('Колонки и примеры'!E:E,MATCH($B14,'Колонки и примеры'!$B:$B,0)),"") | F14: =IFERROR(INDEX('Колонки и примеры'!F:F,MATCH($B14,'Колонки и примеры'!$B:$B,0)),"") | G14: =IFERROR(INDEX('Колонки и примеры'!G:G,MATCH($B14,'Колонки и примеры'!$B:$B,0)),"") | H14: =IFERROR(INDEX('Колонки и примеры'!H:H,MATCH($B14,'Колонки и примеры'!$B:$B,0)),"") | I14: =IFERROR(INDEX('Колонки и примеры'!I:I,MATCH($B14,'Колонки и примеры'!$B:$B,0)),"") | J14: =IFERROR(INDEX('Колонки и примеры'!J:J,MATCH($B14,'Колонки и примеры'!$B:$B,0)),"") | K14: =IFERROR(INDEX('Колонки и примеры'!K:K,MATCH($B14,'Колонки и примеры'!$B:$B,0)),"") | L14: =IFERROR(INDEX('Колонки и примеры'!L:L,MATCH($B14,'Колонки и примеры'!$B:$B,0)),"")
A15: 16 | C15: =IFERROR(INDEX('Колонки и примеры'!C:C,MATCH($B15,'Колонки и примеры'!$B:$B,0)),"") | D15: =IFERROR(INDEX('Колонки и примеры'!D:D,MATCH($B15,'Колонки и примеры'!$B:$B,0)),"") | E15: =IFERROR(INDEX('Колонки и примеры'!E:E,MATCH($B15,'Колонки и примеры'!$B:$B,0)),"") | F15: =IFERROR(INDEX('Колонки и примеры'!F:F,MATCH($B15,'Колонки и примеры'!$B:$B,0)),"") | G15: =IFERROR(INDEX('Колонки и примеры'!G:G,MATCH($B15,'Колонки и примеры'!$B:$B,0)),"") | H15: =IFERROR(INDEX('Колонки и примеры'!H:H,MATCH($B15,'Колонки и примеры'!$B:$B,0)),"") | I15: =IFERROR(INDEX('Колонки и примеры'!I:I,MATCH($B15,'Колонки и примеры'!$B:$B,0)),"") | J15: =IFERROR(INDEX('Колонки и примеры'!J:J,MATCH($B15,'Колонки и примеры'!$B:$B,0)),"") | K15: =IFERROR(INDEX('Колонки и примеры'!K:K,MATCH($B15,'Колонки и примеры'!$B:$B,0)),"") | L15: =IFERROR(INDEX('Колонки и примеры'!L:L,MATCH($B15,'Колонки и примеры'!$B:$B,0)),"")
A16: 17 | C16: =IFERROR(INDEX('Колонки и примеры'!C:C,MATCH($B16,'Колонки и примеры'!$B:$B,0)),"") | D16: =IFERROR(INDEX('Колонки и примеры'!D:D,MATCH($B16,'Колонки и примеры'!$B:$B,0)),"") | E16: =IFERROR(INDEX('Колонки и примеры'!E:E,MATCH($B16,'Колонки и примеры'!$B:$B,0)),"") | F16: =IFERROR(INDEX('Колонки и примеры'!F:F,MATCH($B16,'Колонки и примеры'!$B:$B,0)),"") | G16: =IFERROR(INDEX('Колонки и примеры'!G:G,MATCH($B16,'Колонки и примеры'!$B:$B,0)),"") | H16: =IFERROR(INDEX('Колонки и примеры'!H:H,MATCH($B16,'Колонки и примеры'!$B:$B,0)),"") | I16: =IFERROR(INDEX('Колонки и примеры'!I:I,MATCH($B16,'Колонки и примеры'!$B:$B,0)),"") | J16: =IFERROR(INDEX('Колонки и примеры'!J:J,MATCH($B16,'Колонки и примеры'!$B:$B,0)),"") | K16: =IFERROR(INDEX('Колонки и примеры'!K:K,MATCH($B16,'Колонки и примеры'!$B:$B,0)),"") | L16: =IFERROR(INDEX('Колонки и примеры'!L:L,MATCH($B16,'Колонки и примеры'!$B:$B,0)),"")
A17: 18 | C17: =IFERROR(INDEX('Колонки и примеры'!C:C,MATCH($B17,'Колонки и примеры'!$B:$B,0)),"") | D17: =IFERROR(INDEX('Колонки и примеры'!D:D,MATCH($B17,'Колонки и примеры'!$B:$B,0)),"") | E17: =IFERROR(INDEX('Колонки и примеры'!E:E,MATCH($B17,'Колонки и примеры'!$B:$B,0)),"") | F17: =IFERROR(INDEX('Колонки и примеры'!F:F,MATCH($B17,'Колонки и примеры'!$B:$B,0)),"") | G17: =IFERROR(INDEX('Колонки и примеры'!G:G,MATCH($B17,'Колонки и примеры'!$B:$B,0)),"") | H17: =IFERROR(INDEX('Колонки и примеры'!H:H,MATCH($B17,'Колонки и примеры'!$B:$B,0)),"") | I17: =IFERROR(INDEX('Колонки и примеры'!I:I,MATCH($B17,'Колонки и примеры'!$B:$B,0)),"") | J17: =IFERROR(INDEX('Колонки и примеры'!J:J,MATCH($B17,'Колонки и примеры'!$B:$B,0)),"") | K17: =IFERROR(INDEX('Колонки и примеры'!K:K,MATCH($B17,'Колонки и примеры'!$B:$B,0)),"") | L17: =IFERROR(INDEX('Колонки и примеры'!L:L,MATCH($B17,'Колонки и примеры'!$B:$B,0)),"")
A18: 19 | C18: =IFERROR(INDEX('Колонки и примеры'!C:C,MATCH($B18,'Колонки и примеры'!$B:$B,0)),"") | D18: =IFERROR(INDEX('Колонки и примеры'!D:D,MATCH($B18,'Колонки и примеры'!$B:$B,0)),"") | E18: =IFERROR(INDEX('Колонки и примеры'!E:E,MATCH($B18,'Колонки и примеры'!$B:$B,0)),"") | F18: =IFERROR(INDEX('Колонки и примеры'!F:F,MATCH($B18,'Колонки и примеры'!$B:$B,0)),"") | G18: =IFERROR(INDEX('Колонки и примеры'!G:G,MATCH($B18,'Колонки и примеры'!$B:$B,0)),"") | H18: =IFERROR(INDEX('Колонки и примеры'!H:H,MATCH($B18,'Колонки и примеры'!$B:$B,0)),"") | I18: =IFERROR(INDEX('Колонки и примеры'!I:I,MATCH($B18,'Колонки и примеры'!$B:$B,0)),"") | J18: =IFERROR(INDEX('Колонки и примеры'!J:J,MATCH($B18,'Колонки и примеры'!$B:$B,0)),"") | K18: =IFERROR(INDEX('Колонки и примеры'!K:K,MATCH($B18,'Колонки и примеры'!$B:$B,0)),"") | L18: =IFERROR(INDEX('Колонки и примеры'!L:L,MATCH($B18,'Колонки и примеры'!$B:$B,0)),"")
A19: 20 | C19: =IFERROR(INDEX('Колонки и примеры'!C:C,MATCH($B19,'Колонки и примеры'!$B:$B,0)),"") | D19: =IFERROR(INDEX('Колонки и примеры'!D:D,MATCH($B19,'Колонки и примеры'!$B:$B,0)),"") | E19: =IFERROR(INDEX('Колонки и примеры'!E:E,MATCH($B19,'Колонки и примеры'!$B:$B,0)),"") | F19: =IFERROR(INDEX('Колонки и примеры'!F:F,MATCH($B19,'Колонки и примеры'!$B:$B,0)),"") | G19: =IFERROR(INDEX('Колонки и примеры'!G:G,MATCH($B19,'Колонки и примеры'!$B:$B,0)),"") | H19: =IFERROR(INDEX('Колонки и примеры'!H:H,MATCH($B19,'Колонки и примеры'!$B:$B,0)),"") | I19: =IFERROR(INDEX('Колонки и примеры'!I:I,MATCH($B19,'Колонки и примеры'!$B:$B,0)),"") | J19: =IFERROR(INDEX('Колонки и примеры'!J:J,MATCH($B19,'Колонки и примеры'!$B:$B,0)),"") | K19: =IFERROR(INDEX('Колонки и примеры'!K:K,MATCH($B19,'Колонки и примеры'!$B:$B,0)),"") | L19: =IFERROR(INDEX('Колонки и примеры'!L:L,MATCH($B19,'Колонки и примеры'!$B:$B,0)),"")
A20: 21 | C20: =IFERROR(INDEX('Колонки и примеры'!C:C,MATCH($B20,'Колонки и примеры'!$B:$B,0)),"") | D20: =IFERROR(INDEX('Колонки и примеры'!D:D,MATCH($B20,'Колонки и примеры'!$B:$B,0)),"") | E20: =IFERROR(INDEX('Колонки и примеры'!E:E,MATCH($B20,'Колонки и примеры'!$B:$B,0)),"") | F20: =IFERROR(INDEX('Колонки и примеры'!F:F,MATCH($B20,'Колонки и примеры'!$B:$B,0)),"") | G20: =IFERROR(INDEX('Колонки и примеры'!G:G,MATCH($B20,'Колонки и примеры'!$B:$B,0)),"") | H20: =IFERROR(INDEX('Колонки и примеры'!H:H,MATCH($B20,'Колонки и примеры'!$B:$B,0)),"") | I20: =IFERROR(INDEX('Колонки и примеры'!I:I,MATCH($B20,'Колонки и примеры'!$B:$B,0)),"") | J20: =IFERROR(INDEX('Колонки и примеры'!J:J,MATCH($B20,'Колонки и примеры'!$B:$B,0)),"") | K20: =IFERROR(INDEX('Колонки и примеры'!K:K,MATCH($B20,'Колонки и примеры'!$B:$B,0)),"") | L20: =IFERROR(INDEX('Колонки и примеры'!L:L,MATCH($B20,'Колонки и примеры'!$B:$B,0)),"")
A21: 22 | C21: =IFERROR(INDEX('Колонки и примеры'!C:C,MATCH($B21,'Колонки и примеры'!$B:$B,0)),"") | D21: =IFERROR(INDEX('Колонки и примеры'!D:D,MATCH($B21,'Колонки и примеры'!$B:$B,0)),"") | E21: =IFERROR(INDEX('Колонки и примеры'!E:E,MATCH($B21,'Колонки и примеры'!$B:$B,0)),"") | F21: =IFERROR(INDEX('Колонки и примеры'!F:F,MATCH($B21,'Колонки и примеры'!$B:$B,0)),"") | G21: =IFERROR(INDEX('Колонки и примеры'!G:G,MATCH($B21,'Колонки и примеры'!$B:$B,0)),"") | H21: =IFERROR(INDEX('Колонки и примеры'!H:H,MATCH($B21,'Колонки и примеры'!$B:$B,0)),"") | I21: =IFERROR(INDEX('Колонки и примеры'!I:I,MATCH($B21,'Колонки и примеры'!$B:$B,0)),"") | J21: =IFERROR(INDEX('Колонки и примеры'!J:J,MATCH($B21,'Колонки и примеры'!$B:$B,0)),"") | K21: =IFERROR(INDEX('Колонки и примеры'!K:K,MATCH($B21,'Колонки и примеры'!$B:$B,0)),"") | L21: =IFERROR(INDEX('Колонки и примеры'!L:L,MATCH($B21,'Колонки и примеры'!$B:$B,0)),"")
... A99: 100 | C99: =IFERROR(INDEX('Колонки и примеры'!C:C,MATCH($B99,'Колонки и примеры'!$B:$B,0)),"") | D99: =IFERROR(INDEX('Колонки и примеры'!D:D,MATCH($B99,'Колонки и примеры'!$B:$B,0)),"") | E99: =IFERROR(INDEX('Колонки и примеры'!E:E,MATCH($B99,'Колонки и примеры'!$B:$B,0)),"") | F99: =IFERROR(INDEX('Колонки и примеры'!F:F,MATCH($B99,'Колонки и примеры'!$B:$B,0)),"") | G99: =IFERROR(INDEX('Колонки и примеры'!G:G,MATCH($B99,'Колонки и примеры'!$B:$B,0)),"") | H99: =IFERROR(INDEX('Колонки и примеры'!H:H,MATCH($B99,'Колонки и примеры'!$B:$B,0)),"") | I99: =IFERROR(INDEX('Колонки и примеры'!I:I,MATCH($B99,'Колонки и примеры'!$B:$B,0)),"") | J99: =IFERROR(INDEX('Колонки и примеры'!J:J,MATCH($B99,'Колонки и примеры'!$B:$B,0)),"") | K99: =IFERROR(INDEX('Колонки и примеры'!K:K,MATCH($B99,'Колонки и примеры'!$B:$B,0)),"") | L99: =IFERROR(INDEX('Колонки и примеры'!L:L,MATCH($B99,'Колонки и примеры'!$B:$B,0)),"")
